File: Data/UCL_Heap/Defm/UH001_DDS-7_scld.txt
time (mins)	time (secs)	stress (Mpa)	strain (%)	strain	pore volume (cm3)	confining pressure (Mpa)	pore pressure (Mpa)	effective pressure (Mpa)
0	0	0	0	0	0	49.93573356	19.99225616	29.9434774
0.3030192	18.181152	1.803299826	0.023213565	0.000232136	-0.00196825	49.8601625	20.03829956	29.82186294
0.6018912	36.113472	3.550725433	0.04081291	0.000408129	-0.00486346	50.19231339	20.02399445	30.16831894
0.9054144	54.324864	5.228986348	0.061481607	0.000614816	-0.0093356	49.90405803	20.02017975	29.88387828
1.2034368	72.206208	7.539765146	0.084888978	0.00084889	-0.0139002	50.32556767	20.05138397	30.2741837
1.5025968	90.155808	9.242843985	0.105752863	0.001057529	-0.01852089	50.1293241	20.02807617	30.10124793
1.8011952	108.071712	11.3476205	0.124932222	0.001249322	-0.02185965	49.9198154	20.06462097	29.85519443
2.1020688	126.124128	13.28396064	0.145781077	0.001457811	-0.0254881	50.04153304	20.0479126	29.99362044
2.4035904	144.215424	15.18721023	0.166679431	0.001666794	-0.02803751	50.05162258	20.03662109	30.01500149
2.7025488	162.152928	16.92934678	0.185869892	0.001858699	-0.03126194	50.01480179	20.0214386	29.99336319
3.0024432	180.146592	18.72776439	0.206626936	0.002066269	-0.03265291	49.87937684	20.03925323	29.84012361
3.3002064	198.012384	20.58883708	0.22616568	0.002261657	-0.03765046	49.90180697	20.04112244	29.86068453
3.6014112	216.084672	22.19264424	0.24594818	0.002459482	-0.04260267	50.00153666	20.03074646	29.9707902
3.9028608	234.171648	24.3766211	0.266475349	0.002664753	-0.04716708	49.88227105	20.03303528	29.84923577
4.2007248	252.043488	26.01202704	0.285762931	0.002857629	-0.04728247	50.07951956	20.01407623	30.06544333
4.4999424	269.996544	28.0559115	0.30537799	0.00305378	-0.05205454	49.84565125	20.0510788	29.79457245
4.8038976	288.233856	29.60723486	0.325266414	0.003252664	-0.05619252	50.08546877	20.03631592	30.04915285
5.1033744	306.202464	31.66495227	0.346103949	0.003461039	-0.06038132	50.06010423	20.03940582	30.02069841
5.4027072	324.162432	33.40858059	0.364238444	0.003642384	-0.06018125	50.04663811	20.03845215	30.00818596
5.7022848	342.137088	34.95488612	0.384550069	0.003845501	-0.06477971	50.02806692	20.05203247	29.97603445
6.0025392	360.152352	37.19107555	0.402851073	0.004028511	-0.06840958	49.95744014	20.03890991	29.91853023
6.3004608	378.027648	38.73412627	0.416814461	0.004168145	-0.0728302	49.87149816	20.06484985	29.80664831
6.6017664	396.105984	40.69917203	0.435742425	0.004357424	-0.07294153	49.86639309	20.0082016	29.85819149
6.9036912	414.221472	42.65101772	0.456068164	0.004560682	-0.07613085	49.87285817	20.02636592	29.84649225
7.2023904	432.143424	44.72690781	0.478341857	0.004783419	-0.08151372	50.13117318	20.05172729	30.07944589
7.5027024	450.162144	46.69240562	0.499726094	0.004997261	-0.08975581	49.8601223	20.01758575	29.84253655
7.8019776	468.118656	48.25267971	0.521357331	0.005213573	-0.09452894	49.84500809	20.03101349	29.8139946
8.1014976	486.089856	50.03848494	0.543893288	0.005438933	-0.0992682	49.9235236	20.03827095	29.88525265
8.4011904	504.071424	52.21378232	0.564356161	0.005643562	-0.10219834	49.8769248	20.03952026	29.83740454
8.7016032	522.096192	53.90018025	0.583110907	0.005831109	-0.10741396	49.97926731	20.03593445	29.94333286
9.0012384	540.074304	55.68571425	0.607477094	0.006074771	-0.11229189	49.97862415	20.03105164	29.94757251
9.3011328	558.067968	57.68267522	0.628940439	0.006289404	-0.11739106	49.94891829	20.01564026	29.93327803
9.6009264	576.055584	59.09905962	0.651715059	0.006517151	-0.11963101	50.05692863	20.01522064	30.04170799
9.9002016	594.012096	61.39478494	0.673253322	0.006732533	-0.12571043	49.92805586	20.02536774	29.90268812
10.2013488	612.080928	63.03642925	0.694759677	0.006947597	-0.13154002	49.84428453	20.03684998	29.80743455
10.5010416	630.062496	65.01087779	0.715350212	0.007153502	-0.13584526	49.97040379	20.02868652	29.94171727
10.8013536	648.081216	67.03577586	0.737128535	0.007371285	-0.13908557	50.03373475	20.02361298	30.01012177
11.1017664	666.105984	69.09173024	0.757853672	0.007578537	-0.14197761	50.06910844	20.04779816	30.02131028
11.4012432	684.074592	71.00949086	0.780391011	0.00780391	-0.14595574	50.01472139	20.25753021	29.75719118
11.7009792	702.058752	72.83855792	0.803561085	0.008035611	-0.1522871	50.01021929	20.02841949	29.9817998
12.0017664	720.105984	74.77476246	0.826077603	0.008260776	-0.15618267	49.90417862	20.01571655	29.88846207
12.3014448	738.086688	76.42888353	0.84736888	0.008473689	-0.15886088	49.87206092	20.00114441	29.87091651
12.6014544	756.087264	78.5873644	0.869852108	0.008698521	-0.16022221	49.94164257	20.00411987	29.9375227
12.9027024	774.162144	79.76275731	0.891118402	0.008911184	-0.16485666	49.9931756	20.01396179	29.97921381
13.204008	792.24048	82.26136573	0.915724649	0.009157246	-0.17225189	50.00897317	20.02040863	29.98856454
13.5038016	810.228096	84.16787012	0.939238846	0.009392388	-0.18406034	50.09330726	20.03341675	30.05989051
13.8019824	828.118944	86.01899756	0.960981086	0.009609811	-0.18761293	50.07188206	20.02593994	30.04594212
14.0995296	845.971776	87.8478386	0.980997171	0.009809972	-0.1908056	49.98240271	20.02944946	29.95295325
14.402592	864.15552	89.16260063	1.002551163	0.010025512	-0.19197868	50.04756265	20.04131317	30.00624948
14.7007152	882.042912	91.13926425	1.025604212	0.010256042	-0.19462918	49.81498065	20.03166199	29.78331866
15.0020208	900.121248	92.92289961	1.049251629	0.010492516	-0.19499969	49.98927646	20.03509521	29.95418125
15.3017136	918.102816	95.00719795	1.071811171	0.010718112	-0.19784409	49.90088243	20.04695892	29.85392351
15.6017088	936.102528	96.43348239	1.093449349	0.010934493	-0.19976117	50.06802311	20.01621246	30.05181065
15.9034752	954.208512	98.68458971	1.120325687	0.011203257	-0.2031952	49.94107981	20.04055023	29.90052958
16.2035424	972.212544	99.79949742	1.145112325	0.011451123	-0.2029602	49.89477243	20.02174377	29.87302866
16.5038544	990.231264	101.8888136	1.16750396	0.01167504	-0.20329894	50.03084054	20.04066467	29.99017587
16.801416	1008.08496	103.6185864	1.188789679	0.011887897	-0.20412146	50.01649678	20.01819611	29.99830067
17.1040032	1026.240192	105.2990398	1.21780155	0.012178015	-0.20701561	49.90772939	20.01994451	29.88778488
17.4036384	1044.218304	107.594087	1.242486876	0.012424869	-0.20907031	50.07417331	20.03662109	30.03755222
17.701632	1062.09792	109.7274561	1.268399538	0.012683995	-0.21235543	49.87495513	20.02792358	29.84703155
18.0018864	1080.113184	111.3115762	1.291528466	0.012915285	-0.21339372	50.01492238	20.01724243	29.99767995
18.29952	1097.9712	112.991781	1.317816693	0.013178167	-0.21454528	49.89726467	20.02296448	29.87430019
18.6044688	1116.268128	115.0763505	1.341942833	0.013419428	-0.2134994	49.82764282	20.06187439	29.76576843
18.9000432	1134.002592	117.115624	1.37056894	0.013705689	-0.21377463	49.86852355	20.02571106	29.84281249
19.2043152	1152.258912	118.9478103	1.400400878	0.014004009	-0.21219418	49.89159684	20.0182724	29.87332444
19.50552	1170.3312	120.6108821	1.429745754	0.014297458	-0.208125	49.99574823	20.01777649	29.97797174
19.8003024	1188.018144	122.5488496	1.45949998	0.014595	-0.2061751	50.05306969	20.01369476	30.03937493
20.100096	1206.00576	124.4186018	1.489501193	0.014895012	-0.20404312	50.05250692	20.02017975	30.03232717
20.4011424	1224.068544	126.0424803	1.520079647	0.015200796	-0.20019837	50.07654495	20.02952576	30.04701919
20.7018144	1242.108864	128.4476486	1.555516085	0.015555161	-0.19630174	49.8914662	20.03188133	29.85958487
21.0017088	1260.102528	129.5087163	1.587353086	0.015873531	-0.18914998	49.97729764	20.03635406	29.94094358
21.3032736	1278.196416	131.1012672	1.61149597	0.01611496	-0.17928826	49.86731763	20.03822327	29.82909436
21.6036432	1296.218592	131.172873	1.62119103	0.01621191	-0.17590399	50.02846889	20.02696991	30.00149898
21.9039984	1314.239904	130.94802	1.62658882	0.016265888	-0.17371591	50.03401613	20.01632055	30.01769558
22.2050448	1332.302688	131.0293902	1.63197136	0.016319714	-0.17034539	49.89513421	20.05405426	29.84107995
22.5011376	1350.068256	131.120118	1.63613415	0.016361342	-0.16890784	50.12759562	20.03379822	30.0937974
22.8023856	1368.143136	131.0371204	1.63922119	0.016392212	-0.16619047	49.89244099	20.04512787	29.84731312
23.100768	1386.04608	131.1163207	1.64294243	0.016429424	-0.16550134	49.84203348	20.0736618	29.76837168
23.40432	1404.2592	131.054615	1.6453743	0.016453743	-0.16308566	49.79319367	20.0333786	29.75981507
23.7021264	1422.127584	130.8940444	1.64625168	0.016462517	-0.16195616	50.01661067	20.01296997	30.0036407
24.002064	1440.12384	131.0384313	1.64903228	0.016490323	-0.16055919	49.90835915	20.04196167	29.86639748
24.3017712	1458.106272	130.9954859	1.65114784	0.016511478	-0.16104366	50.04390469	20.05336761	29.99053708
24.602328	1476.13968	130.9917565	1.65271584	0.016527158	-0.16031924	49.94980264	20.01224518	29.93755746
24.9033744	1494.202464	131.013523	1.6548872	0.016548872	-0.15949073	50.05045686	20.0227356	30.02772126
25.200144	1512.00864	131.0832302	1.6567421	0.016567421	-0.15916575	50.01697245	20.04283905	29.9741334
25.5036384	1530.218304	130.9674132	1.65787125	0.016578713	-0.15781288	49.85879579	20.01068115	29.84811464
25.8014448	1548.086688	130.9364925	1.65907955	0.016590796	-0.15659128	49.92841763	20.04722595	29.88119168
26.1020592	1566.123552	131.0644246	1.6604716	0.016604716	-0.15378429	50.03272982	20.04013062	29.9925992
26.4022272	1584.133632	131.0433588	1.66204643	0.016620464	-0.1517684	50.09856641	20.01368205	30.08488436
26.7021936	1602.131616	131.0779863	1.66369581	0.016636958	-0.14570204	49.94787316	20.02948761	29.91838555
27.0032688	1620.196128	131.1332729	1.6653347	0.016653347	-0.1501456	49.88182888	20.01285553	29.86897335
27.3003984	1638.023904	130.9759571	1.66587544	0.016658754	-0.14742823	50.11135588	20.03067017	30.08068571
27.6038496	1656.230976	130.9244226	1.66629124	0.016662912	-0.1458139	49.88830066	20.01140594	29.87689472
27.9011376	1674.068256	130.9408323	1.66716862	0.016671686	-0.1434702	49.99659908	20.02452215	29.97207693
28.202112	1692.12672	131.0899658	1.66948621	0.016694862	-0.14281829	49.89786763	20.01552582	29.88234181
28.5027552	1710.165312	131.0896042	1.67056084	0.016705608	-0.14282341	49.7607142	20.01533508	29.74537912
28.8004032	1728.024192	131.0887905	1.6716528	0.016716528	-0.13994514	49.9396327	20.01823425	29.92139845
29.1038976	1746.233856	131.0307464	1.67234516	0.016723452	-0.13910886	49.90786338	20.03116608	29.8766973
29.4005088	1764.030528	131.0093189	1.67337799	0.01673378	-0.13877223	49.75501287	20.0495402	29.70547267
29.704464	1782.26784	131.0870275	1.67455483	0.016745548	-0.13725741	49.90570612	20.01144409	29.89426203
30.0027024	1800.162144	131.0837726	1.67549515	0.016754952	-0.13863356	49.84697776	20.01174927	29.83522849
30.2999472	1817.996832	131.0448505	1.6762352	0.016762352	-0.13751252	49.71874814	20.02937317	29.68937497
30.603168	1836.19008	131.1250002	1.67722511	0.016772251	-0.13577222	49.32372856	20.00934601	29.31438255
30.9009312	1854.055872	131.0219313	1.67789555	0.016778956	-0.13385408	49.35451305	20.02073924	29.33377381
31.2048288	1872.289728	130.9967065	1.67835331	0.016783533	-0.13367729	49.38567271	20.01979828	29.36587443
31.502592	1890.15552	131.0144723	1.67918778	0.016791878	-0.13343064	49.79725361	20.03845215	29.75880146
31.8002976	1908.017856	131.0204395	1.67971611	0.016797161	-0.13179302	49.87901506	20.04493713	29.83407793
32.103792	1926.22752	131.1683977	1.68122769	0.016812277	-0.13088794	49.85968013	20.03677368	29.82290645
32.4004608	1944.027648	131.1481907	1.6823616	0.016823616	-0.13028137	49.77160769	20.04089355	29.73071414
32.7043584	1962.261504	131.1418167	1.68332863	0.016833286	-0.13075456	49.96777086	20.02422333	29.94354753
33.0027552	1980.165312	131.1556497	1.68427754	0.016842775	-0.12969598	50.07558022	20.00835419	30.06722603
33.2999856	1997.999136	131.1674484	1.68478298	0.01684783	-0.12741368	49.91274066	20.02147675	29.89126391
33.6030624	2016.183744	131.1717881	1.68534947	0.016853495	-0.1272369	50.09792995	20.039711	30.05821895
33.9008256	2034.049536	131.1236441	1.68575001	0.0168575	-0.1244052	50.01411843	20.00816345	30.00595498
34.201584	2052.09504	130.9891572	1.6860412	0.016860412	-0.12167319	50.05467758	20.00724792	30.04742966
34.5024432	2070.146592	130.9061143	1.68605995	0.0168606	-0.12152269	49.92045856	20.03978729	29.88067127
34.800048	2088.00288	130.9516816	1.6866045	0.016866045	-0.12056045	50.01733422	20.04489899	29.97243523
35.1034272	2106.205632	130.9655146	1.6870842	0.016870842	-0.11953363	49.8938077	20.02628326	29.86752444
35.400672	2124.04032	130.9694475	1.68786812	0.016878681	-0.11820299	49.88359756	20.02067566	29.8629219
35.7046848	2142.281088	131.1193043	1.68948269	0.016894827	-0.12110879	49.94107981	20.00499725	29.93608256
36.0038448	2160.230688	131.1117098	1.69005966	0.016900597	-0.11845388	49.96889639	20.02300262	29.94589377
36.3009888	2178.059328	131.1255427	1.69060612	0.016906061	-0.11661618	50.09330726	20.06999969	30.02330757
36.6018912	2196.113472	131.1196886	1.69090096	0.01690901	-0.11721128	49.89923434	20.01972198	29.87951236
36.9034272	2214.205632	131.121881	1.69157505	0.016915751	-0.11705338	49.9244113	20.0208346	29.9035767
37.2002976	2232.017856	131.1095399	1.69208718	0.016920872	-0.11701421	50.15774364	20.02155304	30.1361906
37.5040512	2250.243072	131.0769918	1.69254303	0.01692543	-0.11634519	49.92162428	20.03643036	29.88519392
37.8020304	2268.121824	131.0999111	1.69302654	0.016930265	-0.11420474	50.11843061	20.03921509	30.07921552
38.1001536	2286.009216	131.1015385	1.69363213	0.016936321	-0.11395386	50.01435962	20.03700256	29.97735706
38.4041664	2304.249984	131.0668205	1.69386482	0.016938648	-0.11320227	49.99048238	20.04211426	29.94836812
38.7020736	2322.124416	130.9482912	1.69425583	0.016942558	-0.11382683	50.10830088	20.02723694	30.08106394
39.0002544	2340.015264	131.1266276	1.69488621	0.016948862	-0.11319486	49.86812158	20.0409317	29.82718988
39.3038496	2358.230976	131.1414099	1.6956377	0.016956377	-0.11246338	50.00420308	20.03583908	29.968364
39.6007776	2376.046656	131.1827731	1.69633293	0.016963329	-0.11165992	50.07658515	20.05046844	30.02611671
39.902112	2394.12672	131.1569832	1.69676924	0.016967692	-0.10838274	50.10383897	20.02773285	30.07610612
40.203216	2412.19296	131.1503606	1.69671822	0.016967182	-0.10659886	50.24051003	20.02620697	30.21430306
40.5005616	2430.033696	131.1633798	1.69736386	0.016973639	-0.10612038	50.35173616	20.01369476	30.3380414
40.8027168	2448.163008	131.1131337	1.69805352	0.016980535	-0.10738591	50.33224044	20.01255035	30.31969009
41.1037488	2466.224928	131.0558355	1.69819355	0.016981936	-0.10729011	50.23825898	20.03761292	30.20064606
41.4011808	2484.070848	131.0547506	1.69843865	0.016984387	-0.10549158	50.38160281	20.03005981	30.351543
41.7044736	2502.268416	131.0700753	1.69854927	0.016985493	-0.10503957	50.21217089	20.01361847	30.19855242
42.0022368	2520.134208	131.0406464	1.69883442	0.016988344	-0.10463096	50.15018654	20.03486633	30.11532021
42.30036	2538.0216	131.0543437	1.69924259	0.016992426	-0.10357873	50.06388278	20.04470825	30.01917453
42.604416	2556.26496	131.0074202	1.69955254	0.016995525	-0.10393441	49.85783105	20.02376556	29.83406549
42.9027984	2574.167904	131.1768059	1.7002306	0.017002306	-0.0991634	49.84854546	20.04558563	29.80295983
43.2004608	2592.027648	131.1719237	1.70082474	0.017008247	-0.10086983	50.00479264	20.01796722	29.98682542
43.5015072	2610.090432	131.1813943	1.70192703	0.01701927	-0.10063747	50.02983561	20.0415802	29.98825541
43.8020784	2628.124704	131.1412743	1.70250893	0.017025089	-0.09967469	50.28782234	20.02254486	30.26527748
44.10432	2646.2592	131.1426304	1.70303631	0.017030363	-0.10049297	50.13563509	20.00152588	30.13410921
44.4026448	2664.158688	131.1797895	1.70358181	0.017035818	-0.10050144	50.18045516	20.04673004	30.13372512
44.7002064	2682.012384	131.1070988	1.70377064	0.017037706	-0.09840757	50.03110182	19.98812358	30.04297824
45.00216	2700.1296	131.0823939	1.70397663	0.017039766	-0.09712652	49.95707836	20.03463745	29.92244091
45.30348	2718.2088	131.048241	1.70413494	0.017041349	-0.09522231	49.89707708	20.01854579	29.87853129
45.6006672	2736.040032	130.9769064	1.70427799	0.01704278	-0.09505929	49.83170276	20.03002167	29.80168109
45.9017136	2754.102816	131.0033969	1.7044185	0.017044185	-0.09319919	50.0100183	20.0579071	29.9521112
46.2018672	2772.112032	131.0011819	1.70451927	0.017045193	-0.0934005	50.07541943	20.0377655	30.03765393
46.5030288	2790.181728	131.0092737	1.7047801	0.017047801	-0.0923982	49.97701626	20.02807617	29.94894009
46.8047376	2808.284256	130.9756859	1.70488644	0.017048864	-0.09339944	50.03928199	20.00476837	30.03451362
47.102904	2826.17424	131.026271	1.70521069	0.017052107	-0.09307763	50.05254042	20.02153397	30.03100645
47.4007248	2844.043488	131.0170491	1.70561505	0.017056151	-0.09273042	49.92331257	20.0756073	29.84770527
47.7021168	2862.127008	130.980116	1.70574649	0.017057465	-0.09089502	49.88783169	20.01838684	29.86944485
48.00348	2880.2088	130.9572419	1.70607281	0.017060728	-0.08977381	49.95764112	20.0289917	29.92864942
48.301344	2898.08064	130.8929595	1.70636559	0.017063656	-0.08921276	49.94785976	20.05516688	29.89269288
48.6026352	2916.158112	130.8776121	1.70640453	0.017064045	-0.08841795	49.93742185	20.01155853	29.92586332
48.9022848	2934.137088	130.8817937	1.70662546	0.017066255	-0.08588883	50.0131537	20.05031586	29.96283784
49.2038496	2952.230976	130.8945869	1.70701218	0.017070122	-0.08586871	50.01275172	20.03486633	29.97788539
49.5014544	2970.087264	130.8793978	1.70701695	0.01707017	-0.08492658	49.88102493	20.00041962	29.88060531
49.8002544	2988.015264	130.8764142	1.70728207	0.017072821	-0.0880822	50.02470374	20.00424067	30.02046307
50.1047856	3006.287136	130.854173	1.70762444	0.017076244	-0.08515735	49.97247396	20.04962921	29.92284475
50.4030096	3024.180576	130.8799402	1.70804405	0.017080441	-0.084374	50.07968035	20.02044678	30.05923357
50.7009744	3042.058464	131.0247792	1.7088747	0.017088747	-0.08523674	49.95707836	20.02552032	29.93155804
51.0029856	3060.179136	130.8622422	1.70903031	0.017090303	-0.08155395	49.98987942	20.02540588	29.96447354
51.30432	3078.2592	131.0315601	1.70981026	0.017098103	-0.08100031	50.02765155	20.02674739	30.00090416
51.602544	3096.15264	131.0230162	1.710392	0.01710392	-0.08147455	49.97870455	20.04138947	29.93731508
51.9007248	3114.043488	130.9931805	1.71073151	0.017107315	-0.08041492	50.0252732	20.03342311	29.99185009
52.2024192	3132.145152	130.9829414	1.71103621	0.017110362	-0.07931329	50.06014442	20.05146027	30.00868415
52.5038976	3150.233856	130.9938585	1.71141625	0.017114163	-0.07870108	50.00611916	19.9962616	30.00985756
52.802496	3168.14976	131.0082339	1.71179295	0.01711793	-0.07913827	49.96551311	20.00335058	29.96216253
53.1004608	3186.027648	130.9887051	1.71221638	0.017122164	-0.07839621	49.99984837	20.0409317	29.95891667
53.4035808	3204.214848	130.978127	1.71246815	0.017124682	-0.07713438	49.92310488	20.03974915	29.88335573
53.7004656	3222.027936	130.9718886	1.71266365	0.017126637	-0.07687503	49.94200435	20.02067566	29.92132869
54.0036864	3240.221184	130.9632091	1.71308327	0.017130833	-0.07600382	49.97299652	20.04943848	29.92355804
54.3003984	3258.023904	130.9802968	1.71332932	0.017133293	-0.07314672	49.93231678	20.02246857	29.90984821
54.6028992	3276.173952	130.951546	1.71363735	0.017136374	-0.07252215	49.88074355	20.04146576	29.83927779
54.9002016	3294.012096	130.85241	1.71352673	0.017135267	-0.07367283	49.90712643	20.02232869	29.88479774
55.2043728	3312.262368	131.0114888	1.71410656	0.017141066	-0.07471553	50.04346251	19.99725342	30.04620909
55.5012432	3330.074592	131.0373916	1.71455097	0.01714551	-0.07605463	50.029916	20.02643585	30.00348015
55.8042624	3348.255744	131.0223381	1.71472836	0.017147284	-0.07349287	49.9779743	20.04117966	29.93679464
56.1013488	3366.080928	131.0018599	1.71506596	0.01715066	-0.07122751	49.9395925	20.05207062	29.88752188
56.4038496	3384.230976	131.0316957	1.71537495	0.01715375	-0.07103803	49.9672215	20.05214691	29.91507459
56.70072	3402.0432	131.0146079	1.71581459	0.017158146	-0.07145405	49.9779408	20.01224518	29.96569562
57.004776	3420.28656	131.0456643	1.71660137	0.017166014	-0.07096287	49.87314625	20.02182007	29.85132618
57.3023808	3438.142848	131.0433588	1.71680451	0.017168045	-0.06820421	50.023806	20.02735138	29.99645462
57.60072	3456.0432	131.0567849	1.71710873	0.017171087	-0.06681007	49.93078928	20.02838135	29.90240793
57.9026736	3474.160416	131.0610342	1.71742741	0.017174274	-0.06696321	49.90997374	20.01209259	29.89788115
58.2044112	3492.264672	131.0491903	1.71766281	0.017176628	-0.06649567	49.91330342	19.99145508	29.92184834
58.5024336	3510.146016	130.9518173	1.71763706	0.017176371	-0.06368408	50.04129186	20.05840302	29.98288884
58.8013488	3528.080928	131.0215244	1.71791554	0.017179155	-0.0615087	50.01359587	20.00335693	30.01023894
59.10264	3546.1584	130.9911914	1.71799247	0.017179925	-0.06061615	49.97042389	20.02433777	29.94608612
59.4042624	3564.255744	130.9778557	1.71810055	0.017181006	-0.06082486	50.07806575	20.00999451	30.06807124
59.7021264	3582.127584	130.9505967	1.71823311	0.017182331	-0.05831497	49.93444724	19.99671936	29.93772788
60.0008832	3600.052992	130.9438159	1.71834469	0.017183447	-0.05729133	49.9427279	20.04135132	29.90137658
60.3025488	3618.152928	130.9623728	1.71844546	0.017184455	-0.05673646	49.93439364	20.02642949	29.90796415
60.6041568	3636.249408	130.9569707	1.71858216	0.017185822	-0.05630685	49.93589435	20.03448486	29.90140949
60.9025968	3654.155808	130.9252363	1.71874237	0.017187424	-0.05736543	50.07654495	20.0157547	30.06079025
61.2007776	3672.046656	130.9305254	1.71883488	0.017188349	-0.05757397	49.86189098	20.0164032	29.84548778
61.5023712	3690.142272	130.9137767	1.71897714	0.017189771	-0.05403002	50.00374751	20.02861023	29.97513728
61.804368	3708.26208	130.9550721	1.71897316	0.017189732	-0.05334071	49.9549077	20.03799438	29.91691332
62.1021312	3726.127872	130.9401542	1.7191658	0.017191658	-0.05411771	49.88713493	20.01777649	29.86935844
62.4005712	3744.034272	130.9408323	1.71925163	0.017192516	-0.05371651	49.87487473	20.00171661	29.87315812
62.7022368	3762.134208	130.9269993	1.71944364	0.017194436	-0.04890562	49.9701827	20.01342773	29.95675497
63.0042624	3780.255744	130.9413748	1.71966267	0.017196627	-0.04941021	50.00252819	20.04963557	29.95289262
63.3020256	3798.121536	130.9617173	1.71990299	0.01719903	-0.05012793	50.01524396	20.02593994	29.98930402
63.6007248	3816.043488	131.096385	1.72060394	0.017206039	-0.05098538	49.9565357	20.00459035	29.95194535
63.9026352	3834.158112	131.0726746	1.72107045	0.017210705	-0.05135888	49.85734868	20.03059387	29.82675481
64.2039984	3852.239904	131.0736014	1.72146225	0.017214623	-0.05120133	50.00945554	20.05844116	29.95101438
64.5017184	3870.103104	131.032645	1.72169876	0.017216988	-0.05117698	50.07042825	20.0387001	30.03172815
64.80036	3888.0216	131.0593616	1.72213173	0.017221317	-0.04996491	49.984091	20.03276825	29.95132275
65.1041568	3906.249408	131.0498684	1.72239876	0.017223988	-0.048286	49.90884151	20.02037048	29.88847103
65.4026976	3924.161856	131.0656	1.72262287	0.017226229	-0.04697336	49.9197551	20.01660665	29.90314845
65.7006192	3942.037152	131.0734657	1.72286225	0.017228623	-0.04711204	49.89718428	20.03829956	29.85888472
66.0031056	3960.186336	131.0649897	1.72313595	0.01723136	-0.04728511	50.01632929	20.03025055	29.98607874
66.3046848	3978.281088	131.2055568	1.72366715	0.017236672	-0.04613709	49.92636757	20.01945496	29.90691261
66.6032256	3996.193536	130.9017746	1.72321987	0.017232199	-0.04578458	49.63911715	20.01506805	29.6240491
66.901392	4014.08352	131.2442076	1.7241993	0.017241993	-0.04590632	49.97267494	19.99126434	29.9814106
67.2029856	4032.179136	131.242422	1.72444725	0.017244473	-0.04458574	49.9182812	20.01978556	29.89849564
67.5042192	4050.253152	131.2530227	1.72481823	0.017248182	-0.04485409	49.96769047	20.00549316	29.96219731
67.8028608	4068.171648	131.19308	1.72501087	0.017250109	-0.04296664	49.98324685	20.03894806	29.94429879
68.1012432	4086.074592	131.1971485	1.72512722	0.017251272	-0.04241089	49.9334825	20.03829956	29.89518294
68.4028512	4104.171072	131.0880446	1.7251633	0.017251633	-0.03688723	49.94694862	20.04436493	29.90258369
68.704416	4122.26496	131.1076412	1.72531033	0.017253103	-0.03587628	49.91751075	20.03246943	29.88504132
69.0033744	4140.202464	131.0967919	1.72564507	0.017256451	-0.03511199	49.9427279	20.03620148	29.90652642
69.3010944	4158.065664	131.1221523	1.72556973	0.017255697	-0.03472349	50.03502107	19.99652863	30.03849244
69.6024576	4176.147456	131.0809247	1.72577604	0.01725776	-0.03649555	49.96923137	19.99950409	29.96972728
69.9040512	4194.243072	131.084722	1.72583676	0.017258368	-0.03372102	50.01114383	20.03135681	29.97978702
70.2026496	4212.158976	131.0710246	1.72608948	0.017260895	-0.03109892	49.98127718	20.01720428	29.9640729
70.500456	4230.02736	130.935272	1.72587681	0.017258768	-0.0289426	50.00503383	20.04009247	29.96494136
70.8023664	4248.141984	131.0970857	1.7264452	0.017264452	-0.03044489	49.98196054	20.01815796	29.96380258
71.1018576	4266.111456	131.1090652	1.72655328	0.017265533	-0.03104035	49.94361224	19.99183655	29.95177569
71.4034368	4284.206208	131.0969275	1.72661972	0.017266197	-0.03026158	49.93697298	20.04003525	29.89693773
71.701344	4302.08064	131.1190331	1.72674847	0.017267485	-0.03021501	49.99675317	20.04306793	29.95368524
72.00036	4320.0216	131.2471912	1.7278595	0.017278595	-0.02986991	49.88174849	20.06160736	29.82014113
72.3022416	4338.134496	131.2360932	1.72816102	0.01728161	-0.03162697	50.02453625	20.00277837	30.02175788
72.6039072	4356.234432	131.292216	1.72862721	0.017286272	-0.02932263	50.00101409	20.01922607	29.98178802
72.9023328	4374.139968	131.2871982	1.72906018	0.017290602	-0.02757915	49.9488781	20.04924774	29.89963036
73.2012912	4392.077472	131.2916736	1.72933865	0.017293387	-0.02665924	49.90470119	20.02384186	29.88085933
73.5023664	4410.141984	131.2612954	1.72937219	0.017293722	-0.02763437	49.96454167	20.01975377	29.9447879
73.8040608	4428.243648	131.2821804	1.72965813	0.017296581	-0.02617971	49.8953352	20.03860474	29.85673046
74.1020832	4446.124992	131.2574981	1.72966671	0.017296667	-0.02696411	49.94907908	20.03097534	29.91810374
74.4004656	4464.027936	131.2245431	1.7295084	0.017295084	-0.02529473	49.90847974	20.02464294	29.8838368
74.7025056	4482.150336	131.2810728	1.7292943	0.017292943	-0.0245442	49.96491685	20.03955841	29.92535844
75.0045168	4500.271008	131.3059134	1.72919369	0.017291937	-0.02428591	49.99832087	20.00358582	29.99473505
75.3025392	4518.152352	131.2718735	1.72925186	0.017292519	-0.02466594	50.06122975	20.00518799	30.05604176
75.6011376	4536.068256	131.2900462	1.72944927	0.017294493	-0.02351103	49.91535349	20.00743866	29.90791483
75.9006144	4554.036864	131.2703817	1.72960758	0.017296076	-0.02362747	49.89888597	20.03555298	29.86333299
76.2044112	4572.264672	131.2815023	1.72951508	0.017295151	-0.02194222	49.907515	20.03761292	29.86990208
76.5021312	4590.127872	131.2793324	1.72954178	0.017295418	-0.02180248	49.93585415	20.01346588	29.92238827
76.800888	4608.05328	131.2992681	1.72961045	0.017296105	-0.0213727	49.98107619	20.03803253	29.94304366
77.1025968	4626.155808	131.2916962	1.7297926	0.017297926	-0.02041133	49.8508769	20.03032684	29.82055006
77.404464	4644.26784	131.2580405	1.72997189	0.017299719	-0.01918779	49.97078567	20.01255035	29.95823532
77.7026448	4662.158688	131.3055065	1.73018837	0.017301884	-0.01868391	49.94686823	20.02784729	29.91902094
78.0018624	4680.111744	131.2726872	1.73016453	0.017301645	-0.01774601	49.9763329	19.99950409	29.97682881
78.301368	4698.08208	131.2755351	1.73017009	0.017301701	-0.0179272	49.97207868	20.02048492	29.95159376
78.6020832	4716.124992	131.3339861	1.730649	0.01730649	-0.01753959	49.97227297	20.04371643	29.92855654
78.9010272	4734.061632	131.314186	1.73071861	0.017307186	-0.01706852	50.04331177	20.04933357	29.9939782
79.2024624	4752.147744	131.3470731	1.73085435	0.017308544	-0.01580828	49.9320354	20.01064301	29.92139239
79.5043152	4770.258912	131.3358847	1.73117066	0.017311707	-0.0150858	49.95265665	20.0182724	29.93438425
79.80264	4788.1584	131.3513451	1.73127461	0.017312746	-0.01469413	49.87185993	20.03585815	29.83600178
80.1010944	4806.065664	131.3006243	1.73132134	0.017313213	-0.01147182	49.98869359	20.02938588	29.95930771
80.3998944	4823.993664	131.2983188	1.73140526	0.017314053	-0.01102086	50.00917416	20.01472473	29.99444943
80.7010704	4842.064224	131.3001722	1.73167213	0.017316721	-0.01303834	49.91631823	20.01655579	29.89976244
81.002448	4860.14688	131.3197463	1.73182583	0.017318258	-0.01154803	50.00338573	19.99671936	30.00666637
81.300672	4878.04032	131.3034723	1.73199082	0.017319908	-0.01027139	49.85988111	20.0334549	29.82642621
81.602496	4896.14976	131.3245833	1.73217678	0.017321768	-0.0096006	49.97258115	20.01641591	29.95616524
81.9012384	4914.074304	131.3204018	1.73238739	0.017323874	-0.00762459	49.97195139	20.01911163	29.95283976
82.2024432	4932.146592	131.2951996	1.73248673	0.017324867	-0.00504095	49.9656404	20.02532959	29.94031081
82.5012432	4950.074592	131.3213737	1.73264981	0.017326498	-0.00379077	49.84991217	20.01979828	29.83011389
82.8025056	4968.150336	131.3130559	1.73290475	0.017329048	-0.00514046	50.02302885	20.04178365	29.9812452
83.104056	4986.24336	131.3136435	1.73317242	0.017331724	-0.0026528	49.99084415	20.02960205	29.9612421
83.4021792	5004.130752	131.3437505	1.73352623	0.017335262	-0.00365104	49.98935685	19.99423981	29.99511704
83.7008208	5022.049248	131.3183901	1.73383427	0.017338343	-0.00428724	49.83753138	20.00221252	29.83531886
84.0000384	5040.002304	131.3499889	1.73409653	0.017340965	-0.00348908	49.89342582	20.01622518	29.87720064
84.304368	5058.26208	131.3598889	1.73436833	0.017343683	-0.00098342	50.00418968	20.0346756	29.96951408
84.602232	5076.13392	131.3590752	1.73444843	0.017344484	-0.00078547	49.97460442	20.02681732	29.9477871
84.9015072	5094.090432	131.3536506	1.73470402	0.01734704	-0.00060657	49.90835915	20.02639771	29.88196144
85.199832	5111.98992	131.3745356	1.73524571	0.017352457	-0.00121101	49.93891585	20.03523509	29.90368076
85.50432	5130.2592	131.4036933	1.73576546	0.017357655	0.00023394	49.91792612	20.01743317	29.90049295
85.8024432	5148.146592	131.3931151	1.73605252	0.017360525	-0.00067855	49.99856205	20.02334595	29.9752161
86.1010272	5166.061632	131.3997604	1.73641682	0.017364168	-1.906E-05	49.95128994	20.02658844	29.9247015
86.402592	5184.15552	131.2967818	1.73642302	0.01736423	-0.00010162	49.9074949	20.01434962	29.89314528
86.7042576	5202.255456	131.3752137	1.73713112	0.017371311	0.00064891	49.86609161	20.02016703	29.84592458
87.002496	5220.14976	131.3257135	1.73727608	0.017372761	0.00173607	49.89935493	20.04840851	29.85094642
87.3011952	5238.071712	131.326934	1.73744488	0.017374449	0.00310799	49.9733181	20.03120422	29.94211388
87.9261552	5275.569312	131.2982994	1.73764815	0.017376482	0.00382608	49.91583586	20.03065745	29.88517841
88.6752	5320.512	131.285237	1.7378992	0.017378992	0.00787436	49.95016441	20.0302887	29.91987571
89.4278016	5365.668096	131.3006765	1.7381963	0.017381963	0.0104809	49.92061934	20.02807617	29.89254317
90.17784	5410.6704	131.2498163	1.73840019	0.017384002	0.01208942	50.02042942	20.02696991	29.99345951
90.9284256	5455.705536	131.3123082	1.73879235	0.017387924	0.01568667	50.04004574	20.03192902	30.00811672
91.6770672	5500.624032	131.4263607	1.74001428	0.017400143	0.01457973	49.9167202	20.0252533	29.8914669
92.42604	5545.5624	131.4559058	1.74091574	0.017409157	0.01779161	49.94980264	20.0050354	29.94476724
93.1789872	5590.739232	131.412404	1.74160422	0.017416042	0.01807865	50.00654793	20.04830043	29.9582475
93.9253968	5635.523808	131.4212713	1.74182833	0.017418283	0.01848172	49.96495705	20.014534	29.95042305
94.6777392	5680.664352	131.4235142	1.74244089	0.017424409	0.01899065	49.91812711	20.01277924	29.90534787
95.4249408	5725.496448	131.4161074	1.74272956	0.017427296	0.01982449	49.85529861	20.02830505	29.82699356
96.1777584	5770.665504	131.4007201	1.74328562	0.017432856	0.02619835	49.99810648	20.02328237	29.97482411
96.927048	5815.62288	131.4072774	1.74355752	0.017435575	0.0252691	49.97098665	20.03616333	29.93482332
97.6760064	5860.560384	131.3625909	1.74378337	0.017437834	0.0329928	49.92560382	20.01148224	29.91412158
98.429184	5905.75104	131.4382234	1.74416887	0.017441689	0.03388689	49.9763329	20.0069046	29.9694283
99.1752768	5950.516608	131.4460997	1.74456098	0.01744561	0.03708705	50.02852249	20.00490824	30.02361425
99.9275184	5995.651104	131.3775609	1.74483974	0.017448397	0.0371123	49.99594922	20.01750946	29.97843976
100.6771248	6040.627488	131.3234855	1.74521998	0.0174522	0.0381864	49.9534606	20.04470825	29.90875235
101.4274224	6085.645344	131.270945	1.74552639	0.017455264	0.03822258	49.86426263	20.01853943	29.8457232
102.1770576	6130.623456	131.316075	1.74649586	0.017464959	0.04138407	49.9931488	20.01298269	29.98016611
102.9260016	6175.560096	131.3116823	1.74689014	0.017468901	0.04321011	50.04543219	20.01533508	30.03009711
103.678776	6220.72656	131.4434395	1.74776166	0.017477617	0.04765655	50.03256903	20.00541687	30.02715216
104.4280512	6265.683072	131.4443784	1.74819681	0.017481968	0.04636732	49.89396849	20.01846313	29.87550536
105.1776	6310.656	131.433216	1.74914008	0.017491401	0.04817688	49.96815944	20.04715602	29.92100342
105.9274224	6355.645344	131.441666	1.7495609	0.017495609	0.05075967	49.99916501	19.99908447	30.00008054
106.676928	6400.61568	131.452724	1.75026138	0.017502614	0.05129114	49.94156218	20.02773285	29.91382933
107.4297888	6445.787328	131.4695718	1.75093739	0.017509374	0.05186237	49.95848527	20.03257751	29.92590776
108.1755648	6490.533888	131.4597135	1.75147071	0.017514707	0.05453405	49.92053895	20.02113342	29.89940553
108.9276048	6535.656288	131.4445348	1.75186979	0.017518698	0.05632183	50.06027842	20.01584371	30.04443471
109.6767648	6580.605888	131.4023855	1.7522002	0.017522002	0.05938141	49.96302757	20.03108978	29.93193779
110.4262992	6625.577952	131.458879	1.75261879	0.017526188	0.06161024	49.87821112	20.02937317	29.84883795
111.1782384	6670.694304	131.4362413	1.75303291	0.017530329	0.06306783	50.03088074	20.02765656	30.00322418
111.929832	6715.78992	131.4375975	1.75329077	0.017532908	0.06469071	49.9626658	20.04963557	29.91303023
112.675896	6760.55376	131.4850113	1.75386737	0.017538674	0.06554042	49.93718066	19.99588013	29.94130053
113.4286128	6805.716768	131.4797431	1.75420666	0.017542067	0.06759651	49.94308968	20.01689911	29.92619057
114.1779744	6850.678464	131.4978502	1.75488445	0.017548845	0.06760619	49.93006573	20.06153107	29.86853466
114.9272064	6895.632384	131.4622694	1.75516363	0.017551636	0.06778013	49.92009008	20.01555761	29.90453247
115.6770288	6940.621728	131.4967847	1.75574684	0.017557468	0.0692519	49.98742068	20.02058029	29.96684039
116.4273264	6985.639584	131.5074403	1.75601681	0.017560168	0.07303963	49.9779006	20.01064301	29.96725759
117.1769184	7030.615104	131.4670458	1.75643894	0.017564389	0.07294256	50.01874113	20.00907898	30.00966215
117.9259632	7075.557792	131.5035804	1.75687658	0.017568766	0.07439747	49.9411602	20.03825506	29.90290514
118.6784928	7120.709568	131.5003465	1.75724008	0.017572401	0.07417801	49.74218321	20.03151576	29.71066745
119.4274656	7165.647936	131.4913116	1.75752034	0.017575203	0.07732432	49.91270046	20.00377655	29.90892391
120.1760496	7210.562976	131.446204	1.75773709	0.017577371	0.07773891	50.0069633	20.01228333	29.99467997
120.9278592	7255.671552	131.3940436	1.75780788	0.017578079	0.07944526	49.98916256	20.04865011	29.94051245
121.677552	7300.65312	131.377926	1.75797538	0.017579754	0.07992237	49.97782021	20.02571106	29.95210915
122.4274032	7345.644192	131.385072	1.7580474	0.017580474	0.0802229	49.88403974	20.03803253	29.84600721
123.1767792	7390.606752	131.3691593	1.75822674	0.017582267	0.0818936	49.84191289	20.03578186	29.80613103
123.9256944	7435.541664	131.3711452	1.75850993	0.017585099	0.08781413	49.91245258	20.02957662	29.88287596
124.6785264	7480.711584	131.3807948	1.75867132	0.017586713	0.08168904	50.06709857	20.02696991	30.04012866
125.4277584	7525.665504	131.3866927	1.75879894	0.017587989	0.08450677	49.84882684	20.03768921	29.81113763
126.1778688	7570.672128	131.3698933	1.75923436	0.017592344	0.08508219	49.81506104	20.02094269	29.79411835
126.9273168	7615.639008	131.5006594	1.76029791	0.017602979	0.08620693	49.99192948	20.01728058	29.9746489
127.6771392	7660.628352	131.4657641	1.76107752	0.017610775	0.08827624	49.98312626	20.02231598	29.96081028
128.4296688	7705.780128	131.4763005	1.76149713	0.017614971	0.09011898	49.88251224	20.04863739	29.83387485
129.1760064	7750.560384	131.4949739	1.76170547	0.017617055	0.09286152	49.89453125	20.02973557	29.86479568
129.928896	7795.73376	131.4744749	1.76181845	0.017618185	0.09260949	49.94140139	20.02735138	29.91405001
130.6779696	7840.678176	131.4504327	1.76201896	0.01762019	0.09924672	49.89457145	20.03139496	29.86317649
131.4278208	7885.669248	131.4604959	1.76228355	0.017622836	0.09939458	49.93300014	20.02388	29.90912014
132.1767504	7930.605024	131.4422957	1.76219743	0.017621974	0.10119678	49.88387895	20.03463745	29.8492415
132.9257376	7975.544256	131.4239836	1.76236461	0.017623646	0.10411461	49.85662513	20.00461578	29.85200935
133.677576	8020.65456	131.4449521	1.76262137	0.017626214	0.10564833	49.80774512	19.99565125	29.81209387
134.4267216	8065.603296	131.4628804	1.7627744	0.017627744	0.10933044	49.97094646	20.02544403	29.94550243
135.1765296	8110.591776	131.4222102	1.76294378	0.017629438	0.11145016	49.92873251	20.0615565	29.86717601
135.9287568	8155.725408	131.4232534	1.7630883	0.017630883	0.11728903	49.87326014	20.02007167	29.85318847
136.678176	8200.69056	131.4341586	1.76311534	0.017631153	0.11639116	49.83857651	20.0226593	29.81591721
137.4279408	8245.676448	131.4336855	1.76375954	0.017637595	0.12385181	49.89702349	20.0252533	29.87177019
138.1766112	8290.596672	131.4222623	1.76496851	0.017649685	0.11820755	49.93488941	20.03154755	29.90334186
138.9259008	8335.554048	131.333694	1.76571274	0.017657127	0.12356844	49.9442956	20.04669189	29.89760371
139.6787472	8380.724832	131.2624429	1.76588734	0.017658873	0.12437418	49.86683526	20.01033783	29.85649743
140.4281664	8425.689984	131.243423	1.76624033	0.017662403	0.12783628	49.85976052	20.00976562	29.8499949
141.1764768	8470.588608	131.2351891	1.76636499	0.01766365	0.13199158	49.96819293	19.98446782	29.98372511
141.9254064	8515.524384	131.2128383	1.76647825	0.017664783	0.13251139	49.98264389	20.04318237	29.93946152
142.6774464	8560.646784	131.2217056	1.76664587	0.017666459	0.13492495	49.83934026	20.05237579	29.78696447
143.4294288	8605.765728	131.2198278	1.76677829	0.017667783	0.13718094	49.88986835	20.03269196	29.85717639
144.1754064	8650.524384	131.199068	1.76712895	0.01767129	0.14049063	49.87515612	20.02124786	29.85390826
144.9268704	8695.612224	131.1745526	1.76739928	0.017673993	0.13951185	49.92705762	20.01600266	29.91105496
145.6790544	8740.743264	131.3466298	1.77166954	0.017716695	0.13844961	49.96439428	20.02071381	29.94368047
146.425176	8785.51056	131.3194542	1.77222964	0.017722296	0.14262122	49.90687184	20.04642487	29.86044697
147.1777632	8830.665792	131.2822638	1.77250767	0.017725077	0.14788317	49.86590498	20.025771	29.84013398
147.9272976	8875.637856	131.2802817	1.77270079	0.017727008	0.14644042	49.94827204	20.0408202	29.90745184
148.6764432	8920.586592	131.2845589	1.77305383	0.017730538	0.14830986	49.83874967	20.00833658	29.83041309
149.4289152	8965.734912	131.279708	1.77319945	0.017731995	0.15095712	49.9211852	20.03901555	29.88216965
150.1759584	9010.557504	131.30897	1.77374048	0.017737405	0.16023149	49.87152598	20.01763857	29.85388741
150.928704	9055.72224	131.337606	1.77386849	0.017738685	0.15916355	49.99878159	20.02228957	29.97649202
151.6754016	9100.524096	131.276787	1.77602709	0.017760271	0.15623861	49.86336283	20.03009503	29.8332678
152.4276288	9145.657728	131.3413616	1.77739085	0.017773909	0.16117118	49.88641447	20.01419067	29.8722238
153.1778832	9190.672992	131.3216934	1.77765342	0.017776534	0.16647742	49.81903749	20.03060854	29.78842895
153.9274608	9235.647648	131.2812728	1.77786475	0.017778648	0.17190028	49.98598027	20.01778529	29.96819498
154.6775712	9280.654272	131.2528975	1.77816149	0.017781615	0.17803556	49.86770723	20.03405644	29.83365079
155.4285456	9325.712736	131.2681805	1.78066379	0.017806638	0.17222274	49.99888981	19.99639364	30.00249617
156.178872	9370.73232	131.3450128	1.783209	0.01783209	0.17570709	49.87106217	20.02262702	29.84843515
156.9253968	9415.523808	131.2245223	1.78394736	0.017839474	0.17553975	49.97328718	20.02397684	29.94931034
157.6793808	9460.762848	131.1746048	1.78534779	0.017853478	0.17342341	49.8005986	20.03364563	29.76695297
158.4268128	9505.608768	131.1604171	1.7857311	0.017857311	0.18125771	49.9327806	20.00076587	29.93201473
159.1767504	9550.605024	131.1490722	1.78598275	0.017859828	0.19232829	49.88327599	20.02259768	29.86067831
159.9261264	9595.567584	131.1365798	1.78627066	0.017862707	0.19366954	49.92980444	20.01878193	29.91102251
160.6770576	9640.623456	131.0765656	1.78654337	0.017865434	0.19605675	49.88001381	20.0202355	29.85977831
161.428392	9685.70352	131.1887924	1.78830198	0.01788302	0.19545202	49.92407632	20.01748766	29.90658866
162.1753344	9730.520064	131.2096566	1.79108965	0.017910897	0.20119196	49.81951677	20.01694899	29.80256778
162.9287712	9775.726272	131.2366756	1.79184232	0.017918423	0.20580248	49.92215259	20.02353668	29.89861591
163.675944	9820.55664	131.1828983	1.79307659	0.017930766	0.20437543	49.82256249	20.0397198	29.78284269
164.428848	9865.73088	131.2596262	1.79694117	0.017969412	0.20050551	49.91510921	20.03859006	29.87651915
165.1759776	9910.558656	131.2508111	1.79781709	0.017978171	0.20682075	49.80349856	20.00825065	29.79524791
165.929112	9955.74672	131.1608866	1.79820516	0.017982052	0.2118095	49.90793553	20.01894437	29.88899116
166.6765008	10000.59005	131.1879057	1.79849529	0.017984953	0.21207374	49.84831863	20.04077094	29.80754769
167.4266832	10045.60099	131.3091004	1.80160836	0.018016084	0.20943038	49.96062501	20.04174453	29.91888048
168.1773408	10090.64045	131.2762132	1.80226157	0.018022616	0.22166894	49.82760262	20.00132341	29.82627921
168.9271776	10135.63066	131.2702558	1.80303308	0.018030331	0.23389639	49.87482018	20.01235144	29.86246874
169.677144	10180.62864	131.220871	1.80653844	0.018065384	0.23758508	49.91563487	20.02757146	29.88806341
170.427096	10225.62576	131.350173	1.81053237	0.018105324	0.24065958	49.92585428	20.0163181	29.90953618
170.9417808	10256.50685	131.306501	1.81290055	0.018129006	0.24310326	49.83503914	20.02240694	29.8126322
171.093816	10265.62896	131.2853674	1.81374455	0.018137446	0.23959495	49.98039902	20.04350516	29.93689386
171.2438208	10274.62925	131.361991	1.81452179	0.018145218	0.24150304	49.75833394	20.02284186	29.73549208
171.3931632	10283.58979	131.3094394	1.81521559	0.018152156	0.23958172	49.94771547	20.00606243	29.94165304
171.5446512	10292.67907	131.3485423	1.8158315	0.018158315	0.24118899	49.79399144	20.01869495	29.77529649
171.6935184	10301.6111	131.417707	1.81628768	0.018162877	0.2423499	49.91767345	20.02894538	29.88872807
171.8430768	10310.58461	131.3869671	1.81662623	0.018166262	0.24173063	49.74829012	20.01961928	29.72867084
171.9919584	10319.5175	131.3553232	1.81694095	0.01816941	0.242918	49.86808712	20.0229781	29.84510902
172.1439504	10328.63702	131.385724	1.81727076	0.018172708	0.24321529	49.73553518	20.03352825	29.70200693
172.2934224	10337.60534	131.3609739	1.81754971	0.018175497	0.24412567	49.89352632	20.00320141	29.89032491
172.443168	10346.59008	131.3226621	1.81788588	0.018178859	0.24367048	49.7875444	20.04513374	29.74241066
172.594656	10355.67936	131.2777954	1.8181537	0.018181537	0.24565267	49.8990148	20.00573965	29.89327515
172.7434368	10364.60621	131.3279737	1.8186369	0.018186369	0.24524511	49.73450264	20.02070291	29.71379973
172.8929952	10373.57971	131.2850283	1.8189675	0.018189675	0.24684709	49.83878059	20.00532884	29.83345175
173.0421216	10382.5273	131.250672	1.81930288	0.018193029	0.24658951	49.70914406	20.04205264	29.66709142
173.1939408	10391.63645	131.2907921	1.8197217	0.018197217	0.24685151	49.8181706	20.01729693	29.80087367
173.3434272	10400.60563	131.2219664	1.81983853	0.018198385	0.24955617	49.73519505	20.03050584	29.70468921
173.4930432	10409.58259	131.1544969	1.81985283	0.018198528	0.25171832	49.82030526	20.04205264	29.77825262
173.64456	10418.6736	131.4149947	1.82090823	0.018209082	0.25191416	49.73374176	20.01363314	29.72010862
173.7933552	10427.60131	131.3905836	1.821606	0.01821606	0.25353907	49.80691644	20.03314678	29.77376966
173.9429136	10436.57482	131.3329464	1.82213211	0.018221321	0.25460471	49.7611334	20.00117983	29.75995357
174.0917808	10445.50685	131.3736315	1.82300631	0.018230063	0.25008105	49.8526796	20.02566411	29.82701549
174.2435568	10454.61341	131.3216449	1.82353401	0.01823534	0.25556096	49.73559371	20.00589371	29.7297
174.3933024	10463.59814	131.3894535	1.8241992	0.018241992	0.25449709	49.72355327	20.01058138	29.71297189
174.5429184	10472.5751	131.3423265	1.82467127	0.018246713	0.26093589	49.69380722	20.03879547	29.65501175
174.6943776	10481.66266	131.3399532	1.8251489	0.018251489	0.264543	49.39906771	20.02620697	29.37286074
174.8432592	10490.59555	131.3650424	1.82592297	0.01825923	0.26475295	49.59895688	20.00474196	29.59421492
174.9931776	10499.59066	131.3404053	1.82655557	0.018265556	0.26755113	49.40609011	20.02229691	29.3837932
175.1423904	10508.54342	131.2000417	1.82683055	0.018268306	0.26837505	49.67727991	20.03649198	29.64078793
175.2939504	10517.63702	131.2036581	1.8277278	0.018277278	0.27194246	49.47794733	20.01891503	29.4590323
175.4436816	10526.6209	131.3491074	1.82993555	0.018299356	0.27041811	49.47139648	20.01676559	29.45463089
175.593168	10535.59008	131.3958953	1.83121348	0.018312135	0.27449893	49.38518416	20.01913511	29.36604905
175.744656	10544.67936	131.3123778	1.83236504	0.01832365	0.27357797	49.19164927	20.00929026	29.18235901
175.8936096	10553.61658	131.3022065	1.83372561	0.018337256	0.27637438	49.25768119	20.00462459	29.2530566
176.0434272	10562.60563	131.3162203	1.83509096	0.01835091	0.2759139	49.30837626	20.02959618	29.27878008
176.1932592	10571.59555	131.3372409	1.83625762	0.018362576	0.27716478	49.47568899	20.01737867	29.45831032
176.342904	10580.57424	131.3560013	1.83743541	0.018374354	0.2805046	49.4279016	20.04742256	29.38047904
176.4930816	10589.5849	131.2556446	1.83853849	0.018385385	0.2804499	49.43148844	20.02333128	29.40815716
176.6422224	10598.53334	131.2316856	1.83956369	0.018395637	0.28523291	49.32049731	20.03008036	29.29041695
176.7938256	10607.62954	131.4053885	1.84100294	0.018410029	0.28249384	49.27467231	20.0336603	29.24101201
176.9434272	10616.60563	131.3633472	1.84240008	0.018424001	0.28889295	49.25038382	20.00729487	29.24308895
177.0933024	10625.59814	131.3592787	1.84379959	0.018437996	0.28740565	49.03181833	20.00840994	29.02340839
177.2450784	10634.7047	131.2884188	1.844944	0.01844944	0.28989242	49.0643263	20.02661569	29.03771061
177.3943776	10643.66266	131.290001	1.84597238	0.018459724	0.28915142	48.85869134	20.02830505	28.83038629
177.5439504	10652.63702	131.1751785	1.84661929	0.018466193	0.29271883	48.68440481	20.02026485	28.66413996
177.6930768	10661.58461	131.1688497	1.84764131	0.018476413	0.2901112	49.22316335	20.0249127	29.19825065
177.844608	10670.67648	131.3040147	1.85018921	0.018501892	0.28767558	49.2318621	20.0128702	29.2189919
177.9942096	10679.65258	131.2799427	1.8516984	0.018516984	0.28939577	49.11191933	20.04020397	29.07171536
178.144344	10688.66064	131.2687543	1.85283566	0.018528357	0.28569075	49.12044471	20.01468113	29.10576358
178.2932976	10697.59786	131.2528193	1.85361052	0.018536105	0.29152352	49.22172	20.00318674	29.21853326
178.442784	10706.56704	131.2446823	1.85440445	0.018544045	0.28679696	49.09691489	20.0286184	29.06829649
178.5929184	10715.5751	131.2833331	1.85501003	0.0185501	0.29311139	48.54416237	20.03872211	28.50544026
178.744464	10724.66784	131.3053709	1.85551071	0.018555107	0.29342808	48.40351794	20.00487401	28.39864393
178.8933456	10733.60074	131.3112476	1.85579841	0.018557984	0.29922732	48.68098804	20.03203172	28.64895632
179.042904	10742.57424	131.2635556	1.85642147	0.018564215	0.30196022	48.71532697	20.02184732	28.69347965
179.1921312	10751.52787	131.2933914	1.85780907	0.018578091	0.304926	48.71196762	20.02792358	28.68404404
179.3436912	10760.62147	131.1643292	1.85936117	0.018593612	0.31014127	48.15611858	20.0366387	28.11947988
179.4932928	10769.59757	131.3677547	1.86156655	0.018615666	0.30689672	48.13858634	19.99494112	28.14364522
179.6429088	10778.57453	131.3369019	1.8639102	0.018639102	0.31199378	48.35656303	20.00392278	28.35264025
179.7944688	10787.66813	131.3347546	1.86624591	0.018662459	0.30997013	48.55796862	20.03303255	28.52493607
179.9435232	10796.61139	131.1796991	1.86782424	0.018678242	0.31722669	48.55892717	20.02764482	28.53128235
180.0936864	10805.62118	131.3578095	1.87115415	0.018711542	0.31577643	48.95203207	20.01811436	28.93391771
180.2427408	10814.56445	131.2773434	1.87368457	0.018736846	0.32336821	48.6904808	20.0101559	28.6803249
180.3947328	10823.68397	131.3680938	1.87772417	0.018777242	0.32953972	48.52260928	20.02438137	28.49822791
180.545256	10832.71536	131.3799603	1.88318634	0.018831863	0.33485643	48.32131432	20.03732828	28.28398604
180.6916896	10841.50138	131.3198367	1.89020062	0.018902006	0.34504613	48.20833761	20.0082234	28.20011421
180.8435664	10850.61398	131.2334939	1.90766478	0.019076648	0.36267322	48.3851663	20.01750653	28.36765977
180.9934272	10859.60563	82.46357074	5.36419296	0.05364193	0.597196	48.49107091	20.02578148	28.46528943
181.1441232	10868.64739	93.6318603	7.26151212	0.072615121	0.73214358	48.20325773	20.0414951	28.16176263
181.2446064	10874.67638	-1.763428417	6.64433146	0.066443315	0.75306903	48.28907912	20.01625941	28.27281971